Workbook

Sheet Members & Roles + Objectives + 
A1: Project — ALS1
A2: Team: Ferran · Luz · Noa · Leyre | Course: Introduction to Bioinformatics 2026–2027
A4: Molecular Analysis of SOD1 Gene Mutations in Amyotrophic Lateral Sclerosis 1 (ALS1)
A6: Project Name:
A7: General Objective: explain the impact of changes in genetic and protein sequences on the

Sheet Gantt
A1: Gantt chart — ALS1
A2: Team: Ferran · Luz · Noa · Leyre | Course: Introduction to Bioinformatics 2026–2027 | Live version
A3: Progress (subtasks completed): | C3: =SUMPRODUCT(--(LEN(Status!$A$5:$A$66)-LEN(SUBSTITUTE(Status!$A$5:$A$66,".",""))=2),--(Status!$L$5:$L$66="Completed"))/SUMPRODUCT(--(LEN(Status!$A$5:$A$66)-LEN(SUBSTITUTE(Status!$A$5:$A$66,".",""))=2)) -> 0.026315789 | D3: Status updated up to: | H3: =Status!C3 -> 46303
A4: ID | B4: Task | C4: Owner | D4: Plan. start | E4: Plan. end | F4: Real start | G4: Real end | H4: Days | I4: Predecessor | J4: Status | K4: September 2026 | U4: October 2026 | AQ4: November 2026
K5: 14/09 | M5: 21/09 | R5: 28/09 | W5: 05/10 | AB5: 12/10 | AG5: 19/10 | AL5: 26/10 | AQ5: 02/11
K6: 46282 | L6: =WORKDAY(K6,1) -> 46283 | M6: =WORKDAY(L6,1) -> 46286 | N6: =WORKDAY(M6,1) -> 46287 | O6: =WORKDAY(N6,1) -> 46288 | P6: =WORKDAY(O6,1) -> 46289 | Q6: =WORKDAY(P6,1) -> 46290 | R6: =WORKDAY(Q6,1) -> 46293 | S6: =WORKDAY(R6,1) -> 46294 | ... AT6: =WORKDAY(AS6,1) -> 46331
A7: =IF(Status!A5="","",Status!A5) -> 1 | B7: =IF(Status!B5="","",Status!B5) -> Project management & setup | C7: =IF(Status!C5="","",Status!C5) | D7: =IF(Status!G5="","",Status!G5) -> 46282 | E7: =IF(Status!H5="","",Status!H5) -> 46321 | F7: =IF(Status!J5="","",Status!J5) | G7: =IF(Status!K5="","",Status!K5) | H7: =IF(Status!I5="","",Status!I5) -> 26 | I7: =IF(Status!F5="","",Status!F5) | J7: =IF(Status!L5="","",Status!L5)
A8: =IF(Status!A6="","",Status!A6) -> 1.1 | B8: =IF(Status!B6="","",Status!B6) -> GitHub environment setup | C8: =IF(Status!C6="","",Status!C6) | D8: =IF(Status!G6="","",Status!G6) -> 46282 | E8: =IF(Status!H6="","",Status!H6) -> 46304 | F8: =IF(Status!J6="","",Status!J6) | G8: =IF(Status!K6="","",Status!K6) | H8: =IF(Status!I6="","",Status!I6) -> 16 | I8: =IF(Status!F6="","",Status!F6) | J8: =IF(Status!L6="","",Status!L6)
A9: =IF(Status!A7="","",Status!A7) -> 1.1.1 | B9: =IF(Status!B7="","",Status!B7) -> Setting up repository | C9: =IF(Status!C7="","",Status!C7) -> Noa & Ferran | D9: =IF(Status!G7="","",Status!G7) -> 46282 | E9: =IF(Status!H7="","",Status!H7) -> 46282 | F9: =IF(Status!J7="","",Status!J7) -> 46282 | G9: =IF(Status!K7="","",Status!K7) -> 46282 | H9: =IF(Status!I7="","",Status!I7) -> 1 | I9: =IF(Status!F7="","",Status!F7) | J9: =IF(Status!L7="","",Status!L7) -> Completed
A10: =IF(Status!A8="","",Status!A8) -> 1.1.2 | B10: =IF(Status!B8="","",Status!B8) -> Repository update to Formal Requirements (name, report/, references/, README) | C10: =IF(Status!C8="","",Status!C8) -> Leyre | D10: =IF(Status!G8="","",Status!G8) -> 46304 | E10: =IF(Status!H8="","",Status!H8) -> 46304 | F10: =IF(Status!J8="","",Status!J8) | G10: =IF(Status!K8="","",Status!K8) | H10: =IF(Status!I8="","",Status!I8) -> 1 | I10: =IF(Status!F8="","",Status!F8) -> 1.1.1 | J10: =IF(Status!L8="","",Status!L8) -> Pending
A11: =IF(Status!A9="","",Status!A9) -> 1.2 | B11: =IF(Status!B9="","",Status!B9) -> Project planning | C11: =IF(Status!C9="","",Status!C9) | D11: =IF(Status!G9="","",Status!G9) -> 46296 | E11: =IF(Status!H9="","",Status!H9) -> 46304 | F11: =IF(Status!J9="","",Status!J9) | G11: =IF(Status!K9="","",Status!K9) | H11: =IF(Status!I9="","",Status!I9) -> 7 | I11: =IF(Status!F9="","",Status!F9) | J11: =IF(Status!L9="","",Status!L9)
A12: =IF(Status!A10="","",Status!A10) -> 1.2.1 | B12: =IF(Status!B10="","",Status!B10) -> Gantt chart (Excel) | C12: =IF(Status!C10="","",Status!C10) -> All | D12: =IF(Status!G10="","",Status!G10) -> 46296 | E12: =IF(Status!H10="","",Status!H10) -> 46303 | F12: =IF(Status!J10="","",Status!J10) -> 46294 | G12: =IF(Status!K10="","",Status!K10) | H12: =IF(Status!I10="","",Status!I10) -> 6 | I12: =IF(Status!F10="","",Status!F10) -> 1.1.1 | J12: =IF(Status!L10="","",Status!L10) -> In progress
A13: =IF(Status!A11="","",Status!A11) -> 1.2.2 | B13: =IF(Status!B11="","",Status!B11) -> Risk assessment | C13: =IF(Status!C11="","",Status!C11) -> Leyre | D13: =IF(Status!G11="","",Status!G11) -> 46300 | E13: =IF(Status!H11="","",Status!H11) -> 46303 | F13: =IF(Status!J11="","",Status!J11) -> 46301 | G13: =IF(Status!K11="","",Status!K11) | H13: =IF(Status!I11="","",Status!I11) -> 4 | I13: =IF(Status!F11="","",Status!F11) -> 1.2.1 (SS) | J13: =IF(Status!L11="","",Status!L11) -> In progress
A14: =IF(Status!A12="","",Status!A12) -> 1.2.3 | B14: =IF(Status!B12="","",Status!B12) -> Gantt v1 export to PDF, Moodle submission and freeze in repo | C14: =IF(Status!C12="","",Status!C12) -> Luz | D14: =IF(Status!G12="","",Status!G12) -> 46304 | E14: =IF(Status!H12="","",Status!H12) -> 46304 | F14: =IF(Status!J12="","",Status!J12) | G14: =IF(Status!K12="","",Status!K12) | H14: =IF(Status!I12="","",Status!I12) -> 1 | I14: =IF(Status!F12="","",Status!F12) -> 1.2.1, 1.2.2 | J14: =IF(Status!L12="","",Status!L12) -> Pending
A15: =IF(Status!A13="","",Status!A13) -> 1.3 | B15: =IF(Status!B13="","",Status!B13) -> Literature review | C15: =IF(Status!C13="","",Status!C13) | D15: =IF(Status!G13="","",Status!G13) -> 46301 | E15: =IF(Status!H13="","",Status!H13) -> 46317 | F15: =IF(Status!J13="","",Status!J13) | G15: =IF(Status!K13="","",Status!K13) | H15: =IF(Status!I13="","",Status!I13) -> 12 | I15: =IF(Status!F13="","",Status!F13) | J15: =IF(Status!L13="","",Status!L13)
A16: =IF(Status!A14="","",Status!A14) -> 1.3.1 | B16: =IF(Status!B14="","",Status!B14) -> Bibliography selection | C16: =IF(Status!C14="","",Status!C14) -> All | D16: =IF(Status!G14="","",Status!G14) -> 46301 | E16: =IF(Status!H14="","",Status!H14) -> 46304 | F16: =IF(Status!J14="","",Status!J14) -> 46301 | G16: =IF(Status!K14="","",Status!K14) | H16: =IF(Status!I14="","",Status!I14) -> 4 | I16: =IF(Status!F14="","",Status!F14) | J16: =IF(Status!L14="","",Status!L14) -> In progress
A17: =IF(Status!A15="","",Status!A15) -> 1.3.2 | B17: =IF(Status!B15="","",Status!B15) -> Extraction of information and storage of sources | C17: =IF(Status!C15="","",Status!C15) -> All | D17: =IF(Status!G15="","",Status!G15) -> 46308 | E17: =IF(Status!H15="","",Status!H15) -> 46316 | F17: =IF(Status!J15="","",Status!J15) | G17: =IF(Status!K15="","",Status!K15) | H17: =IF(Status!I15="","",Status!I15) -> 7 | I17: =IF(Status!F15="","",Status!F15) -> 1.3.1 | J17: =IF(Status!L15="","",Status!L15) -> Pending
A18: =IF(Status!A16="","",Status!A16) -> 1.3.3 | B18: =IF(Status!B16="","",Status!B16) -> In-text citations and reference list (Oxford SCIMED) | C18: =IF(Status!C16="","",Status!C16) -> All | D18: =IF(Status!G16="","",Status!G16) -> 46310 | E18: =IF(Status!H16="","",Status!H16) -> 46317 | F18: =IF(Status!J16="","",Status!J16) | G18: =IF(Status!K16="","",Status!K16) | H18: =IF(Status!I16="","",Status!I16) -> 6 | I18: =IF(Status!F16="","",Status!F16) -> 1.3.1 | J18: =IF(Status!L16="","",Status!L16) -> Pending
... A61: =IF(Status!A59="","",Status!A59) -> M | B61: =IF(Status!B59="","",Status!B59) -> Milestones | C61: =IF(Status!C59="","",Status!C59) | D61: =IF(Status!G59="","",Status!G59) | E61: =IF(Status!H59="","",Status!H59) | F61: =IF(Status!J59="","",Status!J59) | G61: =IF(Status!K59="","",Status!K59) | H61: =IF(Status!I59="","",Status!I59) | I61: =IF(Status!F59="","",Status!F59) | J61: =IF(Status!L59="","",Status!L59)
A62: =IF(Status!A60="","",Status!A60) -> M1 | B62: =IF(Status!B60="","",Status!B60) -> Gantt v1 delivered (Moodle, 22:00) | C62: =IF(Status!C60="","",Status!C60) -> — | D62: =IF(Status!G60="","",Status!G60) -> 46304 | E62: =IF(Status!H60="","",Status!H60) -> 46304 | F62: =IF(Status!J60="","",Status!J60) | G62: =IF(Status!K60="","",Status!K60) | H62: =IF(Status!I60="","",Status!I60) -> 0 | I62: =IF(Status!F60="","",Status!F60) -> 1.2.3 | J62: =IF(Status!L60="","",Status!L60) -> Pending | K62: =IF(K$6=$D62,"◆","") | L62: =IF(L$6=$D62,"◆","") | M62: =IF(M$6=$D62,"◆","") | N62: =IF(N$6=$D62,"◆","") | O62: =IF(O$6=$D62,"◆","") | P62: =IF(P$6=$D62,"◆","") | Q62: =IF(Q$6=$D62,"◆","") | R62: =IF(R$6=$D62,"◆","") | ... AT62: =IF(AT$6=$D62,"◆","")
A63: =IF(Status!A61="","",Status!A61) -> M2 | B63: =IF(Status!B61="","",Status!B61) -> Variants and species selected | C63: =IF(Status!C61="","",Status!C61) -> — | D63: =IF(Status!G61="","",Status!G61) -> 46309 | E63: =IF(Status!H61="","",Status!H61) -> 46309 | F63: =IF(Status!J61="","",Status!J61) | G63: =IF(Status!K61="","",Status!K61) | H63: =IF(Status!I61="","",Status!I61) -> 0 | I63: =IF(Status!F61="","",Status!F61) -> 2.1.2, 2.2.1 | J63: =IF(Status!L61="","",Status!L61) -> Pending | K63: =IF(K$6=$D63,"◆","") | L63: =IF(L$6=$D63,"◆","") | M63: =IF(M$6=$D63,"◆","") | N63: =IF(N$6=$D63,"◆","") | O63: =IF(O$6=$D63,"◆","") | P63: =IF(P$6=$D63,"◆","") | Q63: =IF(Q$6=$D63,"◆","") | R63: =IF(R$6=$D63,"◆","") | ... AT63: =IF(AT$6=$D63,"◆","")
A64: =IF(Status!A62="","",Status!A62) -> M3 | B64: =IF(Status!B62="","",Status!B62) -> Analyses completed | C64: =IF(Status!C62="","",Status!C62) -> — | D64: =IF(Status!G62="","",Status!G62) -> 46315 | E64: =IF(Status!H62="","",Status!H62) -> 46315 | F64: =IF(Status!J62="","",Status!J62) | G64: =IF(Status!K62="","",Status!K62) | H64: =IF(Status!I62="","",Status!I62) -> 0 | I64: =IF(Status!F62="","",Status!F62) -> 2.2.3, 2.3.2 | J64: =IF(Status!L62="","",Status!L62) -> Pending | K64: =IF(K$6=$D64,"◆","") | L64: =IF(L$6=$D64,"◆","") | M64: =IF(M$6=$D64,"◆","") | N64: =IF(N$6=$D64,"◆","") | O64: =IF(O$6=$D64,"◆","") | P64: =IF(P$6=$D64,"◆","") | Q64: =IF(Q$6=$D64,"◆","") | R64: =IF(R$6=$D64,"◆","") | ... AT64: =IF(AT$6=$D64,"◆","")
A65: =IF(Status!A63="","",Status!A63) -> M4 | B65: =IF(Status!B63="","",Status!B63) -> Content freeze | C65: =IF(Status!C63="","",Status!C63) -> — | D65: =IF(Status!G63="","",Status!G63) -> 46316 | E65: =IF(Status!H63="","",Status!H63) -> 46316 | F65: =IF(Status!J63="","",Status!J63) | G65: =IF(Status!K63="","",Status!K63) | H65: =IF(Status!I63="","",Status!I63) -> 0 | I65: =IF(Status!F63="","",Status!F63) -> 3.1.3, 3.3.1, 3.3.2 | J65: =IF(Status!L63="","",Status!L63) -> Pending | K65: =IF(K$6=$D65,"◆","") | L65: =IF(L$6=$D65,"◆","") | M65: =IF(M$6=$D65,"◆","") | N65: =IF(N$6=$D65,"◆","") | O65: =IF(O$6=$D65,"◆","") | P65: =IF(P$6=$D65,"◆","") | Q65: =IF(Q$6=$D65,"◆","") | R65: =IF(R$6=$D65,"◆","") | ... AT65: =IF(AT$6=$D65,"◆","")
A66: =IF(Status!A64="","",Status!A64) -> M5 | B66: =IF(Status!B64="","",Status!B64) -> Status retrospective | C66: =IF(Status!C64="","",Status!C64) -> — | D66: =IF(Status!G64="","",Status!G64) -> 46317 | E66: =IF(Status!H64="","",Status!H64) -> 46317 | F66: =IF(Status!J64="","",Status!J64) | G66: =IF(Status!K64="","",Status!K64) | H66: =IF(Status!I64="","",Status!I64) -> 0 | I66: =IF(Status!F64="","",Status!F64) -> 1.4.3 | J66: =IF(Status!L64="","",Status!L64) -> Pending | K66: =IF(K$6=$D66,"◆","") | L66: =IF(L$6=$D66,"◆","") | M66: =IF(M$6=$D66,"◆","") | N66: =IF(N$6=$D66,"◆","") | O66: =IF(O$6=$D66,"◆","") | P66: =IF(P$6=$D66,"◆","") | Q66: =IF(Q$6=$D66,"◆","") | R66: =IF(R$6=$D66,"◆","") | ... AT66: =IF(AT$6=$D66,"◆","")
A67: =IF(Status!A65="","",Status!A65) -> M6 | B67: =IF(Status!B65="","",Status!B65) -> Final delivery (GitHub, 22:00) | C67: =IF(Status!C65="","",Status!C65) -> — | D67: =IF(Status!G65="","",Status!G65) -> 46321 | E67: =IF(Status!H65="","",Status!H65) -> 46321 | F67: =IF(Status!J65="","",Status!J65) | G67: =IF(Status!K65="","",Status!K65) | H67: =IF(Status!I65="","",Status!I65) -> 0 | I67: =IF(Status!F65="","",Status!F65) -> 3.4.3, 3.4.4, 3.4.5 | J67: =IF(Status!L65="","",Status!L65) -> Pending | K67: =IF(K$6=$D67,"◆","") | L67: =IF(L$6=$D67,"◆","") | M67: =IF(M$6=$D67,"◆","") | N67: =IF(N$6=$D67,"◆","") | O67: =IF(O$6=$D67,"◆","") | P67: =IF(P$6=$D67,"◆","") | Q67: =IF(Q$6=$D67,"◆","") | R67: =IF(R$6=$D67,"◆","") | ... AT67: =IF(AT$6=$D67,"◆","")
A68: =IF(Status!A66="","",Status!A66) -> M7 | B68: =IF(Status!B66="","",Status!B66) -> Oral presentation | C68: =IF(Status!C66="","",Status!C66) -> — | D68: =IF(Status!G66="","",Status!G66) -> 46331 | E68: =IF(Status!H66="","",Status!H66) -> 46331 | F68: =IF(Status!J66="","",Status!J66) | G68: =IF(Status!K66="","",Status!K66) | H68: =IF(Status!I66="","",Status!I66) -> 0 | I68: =IF(Status!F66="","",Status!F66) -> 4.1.4 | J68: =IF(Status!L66="","",Status!L66) -> Pending | K68: =IF(K$6=$D68,"◆","") | L68: =IF(L$6=$D68,"◆","") | M68: =IF(M$6=$D68,"◆","") | N68: =IF(N$6=$D68,"◆","") | O68: =IF(O$6=$D68,"◆","") | P68: =IF(P$6=$D68,"◆","") | Q68: =IF(Q$6=$D68,"◆","") | R68: =IF(R$6=$D68,"◆","") | ... AT68: =IF(AT$6=$D68,"◆","") -> ◆
B70: Legend
B71: Completed — Task bar coloured by status (Status sheet)
B72: In progress — Task bar coloured by status (Status sheet)
B73: Incident — Task bar coloured by status (Status sheet)
B74: Pending — Task bar coloured by status (Status sheet)
B75: Canceled — Task bar coloured by status (Status sheet)
B76: ◆ Milestone — Checkpoint without duration
B77: Holiday — Bank holiday (24/09 La Mercè, 12/10); weekends are not shown
B79: Predecessors are finish-to-start unless marked (SS) = start-to-start.

Sheet Status
A1: Project Status — ALS1
A2: Team: Ferran · Luz · Noa · Leyre | Course: Introduction to Bioinformatics 2026–2027
A3: Updated up to: | C3: 46303 | F3: Predecessors are finish-to-start unless marked (SS) = start-to-start (can start once the predecessor has started).
A4: ID | B4: Task | C4: Owner | D4: Output | E4: Accomplished when | F4: Predecessor | G4: Plan. start | H4: Plan. finish | I4: Duration (working days) | J4: Real start | K4: Real finish | L4: Status | M4: Notes
A5: 1 | B5: Project management & setup | G5: =MIN(G6:G20) -> 46282 | H5: =MAX(H6:H20) -> 46321 | I5: =IF(OR(G5="",H5=""),"",NETWORKDAYS(G5,H5,{46289;46307})) -> 26
A6: 1.1 | B6: GitHub environment setup | G6: =MIN(G7:G8) -> 46282 | H6: =MAX(H7:H8) -> 46304 | I6: =IF(OR(G6="",H6=""),"",NETWORKDAYS(G6,H6,{46289;46307})) -> 16
A7: 1.1.1 | B7: Setting up repository | C7: Noa & Ferran | D7: Shared GitHub repository with folder structure | E7: All members are collaborators and can clone, commit and push | G7: 46282 | H7: 46282 | I7: =IF(OR(G7="",H7=""),"",NETWORKDAYS(G7,H7,{46289;46307})) -> 1 | J7: 46282 | K7: 46282 | L7: Completed | M7: Repository created and folders added on 17/09
A8: 1.1.2 | B8: Repository update to Formal Requirements (name, report/, references/, README) | C8: Leyre | D8: Repository compliant with Formal Requirements | E8: Repo named NFL_ALS1_IB_2026; report/, status/, gantt/, references/ exist; README lists members, roles and structure | F8: 1.1.1 | G8: 46304 | H8: 46304 | I8: =IF(OR(G8="",H8=""),"",NETWORKDAYS(G8,H8,{46289;46307})) -> 1 | L8: Pending | M8: Remove unrelated entries (TTR, serum albumin) from the bibliography file
A9: 1.2 | B9: Project planning | G9: =MIN(G10:G12) -> 46296 | H9: =MAX(H10:H12) -> 46304 | I9: =IF(OR(G9="",H9=""),"",NETWORKDAYS(G9,H9,{46289;46307})) -> 7
A10: 1.2.1 | B10: Gantt chart (Excel) | C10: All | D10: Gantt chart, task details and milestones | E10: All tasks have owner, output, duration, predecessor and completion criteria | F10: 1.1.1 | G10: 46296 | H10: 46303 | I10: =IF(OR(G10="",H10=""),"",NETWORKDAYS(G10,H10,{46289;46307})) -> 6 | J10: 46294 | L10: In progress | M10: First Excel version committed on 29/09
A11: 1.2.2 | B11: Risk assessment | C11: Leyre | D11: Risk register and contingency plans | E11: Each risk has score, category, contingency plan and owner; mandatory risk sentence written | F11: 1.2.1 (SS) | G11: 46300 | H11: 46303 | I11: =IF(OR(G11="",H11=""),"",NETWORKDAYS(G11,H11,{46289;46307})) -> 4 | J11: 46301 | L11: In progress
A12: 1.2.3 | B12: Gantt v1 export to PDF, Moodle submission and freeze in repo | C12: Luz | D12: Gantt v1 PDF on Moodle and in gantt/ | E12: PDF uploaded before 20:00 on 09/10 and committed to gantt/ | F12: 1.2.1, 1.2.2 | G12: 46304 | H12: 46304 | I12: =IF(OR(G12="",H12=""),"",NETWORKDAYS(G12,H12,{46289;46307})) -> 1 | L12: Pending | M12: Moodle deadline 22:00; upload at least 2 h earlier
A13: 1.3 | B13: Literature review | G13: =MIN(G14:G16) -> 46301 | H13: =MAX(H14:H16) -> 46317 | I13: =IF(OR(G13="",H13=""),"",NETWORKDAYS(G13,H13,{46289;46307})) -> 12
A14: 1.3.1 | B14: Bibliography selection | C14: All | D14: List of relevant sources on ALS1 / SOD1 | E14: Key reviews and database entries (OMIM, UniProt, ClinVar, PDB) identified | G14: 46301 | H14: 46304 | I14: =IF(OR(G14="",H14=""),"",NETWORKDAYS(G14,H14,{46289;46307})) -> 4 | J14: 46301 | L14: In progress | M14: Every member searches sources
A15: 1.3.2 | B15: Extraction of information and storage of sources | C15: All | D15: Notes per topic; source PDFs in references/ | E15: Each used source is stored in references/ (PDF preferred) | F15: 1.3.1 | G15: 46308 | H15: 46316 | I15: =IF(OR(G15="",H15=""),"",NETWORKDAYS(G15,H15,{46289;46307})) -> 7 | L15: Pending
A16: 1.3.3 | B16: In-text citations and reference list (Oxford SCIMED) | C16: All | D16: Citations in report.md and reference list | E16: Every statement taken from a source is cited in Oxford SCIMED style | F16: 1.3.1 | G16: 46310 | H16: 46317 | I16: =IF(OR(G16="",H16=""),"",NETWORKDAYS(G16,H16,{46289;46307})) -> 6 | L16: Pending | M16: Done while writing each section
A17: 1.4 | B17: Project monitoring | G17: =MIN(G18:G20) -> 46304 | H17: =MAX(H18:H20) -> 46321 | I17: =IF(OR(G17="",H17=""),"",NETWORKDAYS(G17,H17,{46289;46307})) -> 11
A18: 1.4.1 | B18: Project Status and live Gantt updates (Mon & Thu) | C18: Ferran | D18: Updated Status sheet, live Gantt and status/project_status.md | E18: Real dates, status and notes updated every Monday and Thursday | F18: 1.2.1 | G18: 46304 | H18: 46321 | I18: =IF(OR(G18="",H18=""),"",NETWORKDAYS(G18,H18,{46289;46307})) -> 11 | L18: Pending | M18: Final Gantt must reflect real progress on 26/10
A19: 1.4.2 | B19: Risk monitoring | C19: Leyre | D19: Updated risk register | E19: Score and status of each risk reviewed every week; activated contingencies recorded | F19: 1.2.2 | G19: 46304 | H19: 46321 | I19: =IF(OR(G19="",H19=""),"",NETWORKDAYS(G19,H19,{46289;46307})) -> 11 | L19: Pending
A20: 1.4.3 | B20: Retrospective preparation | C20: Ferran | D20: Status summary for the 22/10 retrospective | E20: Delays, incidents and decisions documented in Notes | F20: 1.4.1 (SS) | G20: 46316 | H20: 46316 | I20: =IF(OR(G20="",H20=""),"",NETWORKDAYS(G20,H20,{46289;46307})) -> 1 | L20: Pending
A21: 2 | B21: Bioinformatic analysis | G21: =MIN(G22:G33) -> 46308 | H21: =MAX(H22:H33) -> 46315 | I21: =IF(OR(G21="",H21=""),"",NETWORKDAYS(G21,H21,{46289;46307})) -> 6
A22: 2.1 | B22: Sequence, mutation and structure analysis | G22: =MIN(G23:G26) -> 46308 | H22: =MAX(H23:H26) -> 46311 | I22: =IF(OR(G22="",H22=""),"",NETWORKDAYS(G22,H22,{46289;46307})) -> 4
A23: 2.1.1 | B23: Disease cause at gene, protein, structure and function level | C23: Luz | D23: Summary of SOD1 gene, protein, structure and function in ALS1 | E23: Cause of ALS1 explained at the four levels with sources | F23: 1.3.1 | G23: 46308 | H23: 46309 | I23: =IF(OR(G23="",H23=""),"",NETWORKDAYS(G23,H23,{46289;46307})) -> 2 | L23: Pending
A24: 2.1.2 | B24: Variant selection and numbering mapping table | C24: Leyre | D24: 2–3 selected variants + legacy ↔ HGVS mapping table | E24: Variants chosen with explicit criteria (ClinVar classification, literature, structure availability); one numbering convention fixed | F24: 1.3.1 | G24: 46308 | H24: 46309 | I24: =IF(OR(G24="",H24=""),"",NETWORKDAYS(G24,H24,{46289;46307})) -> 2 | L24: Pending | M24: Contingency for risks 'too much information' and 'source mismatch'
A25: 2.1.3 | B25: Wild-type vs mutant sequence alignment | C25: Leyre | D25: Pairwise alignments and interpretation | E25: Each selected variant located and described in the alignment | F25: 2.1.2 | G25: 46310 | H25: 46311 | I25: =IF(OR(G25="",H25=""),"",NETWORKDAYS(G25,H25,{46289;46307})) -> 2 | L25: Pending
A26: 2.1.4 | B26: Mapping of variants onto the 3D structure | C26: Ferran | D26: Structure figures with mutated residues highlighted | E26: Each variant mapped onto the SOD1 structure (PDB) with its structural context | F26: 2.1.2 | G26: 46310 | H26: 46311 | I26: =IF(OR(G26="",H26=""),"",NETWORKDAYS(G26,H26,{46289;46307})) -> 2 | L26: Pending
A27: 2.2 | B27: Evolutionary conservation | G27: =MIN(G28:G30) -> 46308 | H27: =MAX(H28:H30) -> 46314 | I27: =IF(OR(G27="",H27=""),"",NETWORKDAYS(G27,H27,{46289;46307})) -> 5
A28: 2.2.1 | B28: Species selection (≥ 2) and ortholog retrieval | C28: Noa | D28: Justified species list and SOD1 ortholog sequences | E28: At least 2 species selected and justified; orthologs (not paralogs) retrieved | F28: 1.3.1 | G28: 46308 | H28: 46309 | I28: =IF(OR(G28="",H28=""),"",NETWORKDAYS(G28,H28,{46289;46307})) -> 2 | L28: Pending | M28: Bos taurus proposed: check its SOD1 UniProt entry (current link O46375 seems to be TTR)
A29: 2.2.2 | B29: Multiple sequence alignment and conservation of mutated residues | C29: Noa | D29: MSA and conservation analysis | E29: Conservation of each selected residue described across species | F29: 2.1.2, 2.2.1 | G29: 46310 | H29: 46311 | I29: =IF(OR(G29="",H29=""),"",NETWORKDAYS(G29,H29,{46289;46307})) -> 2 | L29: Pending
A30: 2.2.3 | B30: Selective pressure in evolution | C30: Noa | D30: Interpretation of evolutionary constraint | E30: Biological implication of conservation explained | F30: 2.2.2 | G30: 46314 | H30: 46314 | I30: =IF(OR(G30="",H30=""),"",NETWORKDAYS(G30,H30,{46289;46307})) -> 1 | L30: Pending
A31: 2.3 | B31: Structure–function impact | G31: =MIN(G32:G33) -> 46314 | H31: =MAX(H32:H33) -> 46315 | I31: =IF(OR(G31="",H31=""),"",NETWORKDAYS(G31,H31,{46289;46307})) -> 2
A32: 2.3.1 | B32: Healthy vs disease differences at gene, protein, structure and function level | C32: Ferran | D32: Comparison table healthy vs disease | E32: Differences described at the four levels for each variant | F32: 2.1.1, 2.1.3, 2.1.4 | G32: 46314 | H32: 46314 | I32: =IF(OR(G32="",H32=""),"",NETWORKDAYS(G32,H32,{46289;46307})) -> 1 | L32: Pending
A33: 2.3.2 | B33: Impact on patient function | C33: Luz | D33: Explanation of the physiological consequences | E33: Link between molecular change and clinical phenotype explained with sources | F33: 2.3.1 | G33: 46315 | H33: 46315 | I33: =IF(OR(G33="",H33=""),"",NETWORKDAYS(G33,H33,{46289;46307})) -> 1 | L33: Pending
A34: 3 | B34: Report writing (BMC Bioinformatics format) | G34: =MIN(G35:G52) -> 46308 | H34: =MAX(H35:H52) -> 46318 | I34: =IF(OR(G34="",H34=""),"",NETWORKDAYS(G34,H34,{46289;46307})) -> 9
A35: 3.1 | B35: Background and Methods | G35: =MIN(G36:G38) -> 46308 | H35: =MAX(H36:H38) -> 46316 | I35: =IF(OR(G35="",H35=""),"",NETWORKDAYS(G35,H35,{46289;46307})) -> 7
A36: 3.1.1 | B36: Report skeleton (BMC sections) and figure plan | C36: Ferran | D36: report/report.md skeleton and list of max. 5 figures/tables | E36: All BMC sections present with owner and word budget | F36: 1.1.2 | G36: 46308 | H36: 46308 | I36: =IF(OR(G36="",H36=""),"",NETWORKDAYS(G36,H36,{46289;46307})) -> 1 | L36: Pending
A37: 3.1.2 | B37: Background | C37: Luz | D37: Background section | E37: Disease context, aims and research gap written and cited | F37: 2.1.1, 3.1.1 | G37: 46310 | H37: 46311 | I37: =IF(OR(G37="",H37=""),"",NETWORKDAYS(G37,H37,{46289;46307})) -> 2 | L37: Pending
A38: 3.1.3 | B38: Methods | C38: Leyre | D38: Methods section | E38: Data sources, tools, versions and numbering convention described for reproducibility | F38: 2.1.3, 2.1.4, 2.2.2 | G38: 46316 | H38: 46316 | I38: =IF(OR(G38="",H38=""),"",NETWORKDAYS(G38,H38,{46289;46307})) -> 1 | L38: Pending
A39: 3.2 | B39: Results | G39: =MIN(G40:G42) -> 46314 | H39: =MAX(H40:H42) -> 46315 | I39: =IF(OR(G39="",H39=""),"",NETWORKDAYS(G39,H39,{46289;46307})) -> 2
A40: 3.2.1 | B40: Mutant sequence findings | C40: Leyre | D40: Results subsection | E40: Sequence findings written with figures/tables referenced | F40: 2.1.3 | G40: 46314 | H40: 46315 | I40: =IF(OR(G40="",H40=""),"",NETWORKDAYS(G40,H40,{46289;46307})) -> 2 | L40: Pending
...

Sheet Risks
A1: Risk management — ALS1
A2: Team: Ferran · Luz · Noa · Leyre | Course: Introduction to Bioinformatics 2026–2027
A4: ID | B4: Risk | C4: Type | D4: L | E4: I | F4: S | G4: Category | H4: We have realized because… | I4: Contingency plan | J4: Related task | K4: Owner | L4: Status
A5: R1 | B5: Using terms we don't understand or including GenAI errors or hallucinations | C5: Scientific | D5: 2 | E5: 3 | F5: =D5*E5 -> 6 | G5: =IF(F5>=6,"High",IF(F5>=3,"Medium","Low")) -> High | H5: SOD1 literature uses highly specialised terminology and the IB GenAI policy makes us liable for any GenAI-generated content. | I5: Each section is cross-read by the other members, who must be able to understand and explain it. GenAI is only used for wording and formatting, outside GitHub, and its output is always checked manually. | J5: 3.4.3 | K5: Luz | L5: Open
A6: R2 | B6: Tight schedule: deadline | C6: Team & planning | D6: 2 | E6: 3 | F6: =D6*E6 -> 6 | G6: =IF(F6>=6,"High",IF(F6>=3,"Medium","Low")) -> High | H6: The final deadline on Moodle is Monday 26/10 at 22:00, and only two working days remain after the 22/10 retrospective. | I6: Content freeze on 21/10; 22–23/10 for integration and review only; 26/10 kept exclusively as a buffer. | J6: 1.4.1 | K6: Ferran | L6: Open
A7: R3 | B7: Uneven contribution | C7: Team & planning | D7: 2 | E7: 3 | F7: =D7*E7 -> 6 | G7: =IF(F7>=6,"High",IF(F7>=3,"Medium","Low")) -> High | H7: Our first Gantt draft assigned several tasks to "All" | I7: Every task has a single owner and a balanced workload; each member commits their own work at least twice a week. Tasks are reassigned early if someone falls behind. | J7: 1.4.1 | K7: Ferran | L7: Open
A8: R4 | B8: "Niche awareness" at the oral presentation | C8: Team & planning | D8: 2 | E8: 3 | F8: =D8*E8 -> 6 | G8: =IF(F8>=6,"High",IF(F8>=3,"Medium","Low")) -> High | H8: Our analysis tasks are split by specialisation, each owned by a single member, while the rubric assesses every member's understanding of the whole project. | I8: Short weekly sync where each member explains their progress to the rest; each section is cross-read by a different member; everyone reads the full report before the presentation; a rehearsal with questions about other members' sections. | J8: 4.1.1 | K8: Noa | L8: Open
A9: R5 | B9: Mismatch between different sources leads to wrong positions in alignments and structures | C9: Scientific | D9: 3 | E9: 2 | F9: =D9*E9 -> 6 | G9: =IF(F9>=6,"High",IF(F9>=3,"Medium","Low")) -> High | H9: The same SOD1 mutation is named A4V in the classic literature but p.Ala5Val in ClinVar. | I9: Before any analysis, define a single numbering convention in Methods and build a mapping table between sources. | J9: 2.1.2 | K9: Leyre | L9: Open
A10: R6 | B10: Trying to analyse too much information (e.g. too many variants) | C10: Scientific | D10: 3 | E10: 2 | F10: =D10*E10 -> 6 | G10: =IF(F10>=6,"High",IF(F10>=3,"Medium","Low")) -> High | H10: ClinVar currently lists 194 SOD1 variants classified as pathogenic or likely pathogenic (consulted 08/10), far more than we can analyse. | I10: Select 2–3 representative variants using explicit criteria by a fixed date (14/10); anything outside that scope is left for the Discussion as future work. | J10: 2.1.2 | K10: Leyre | L10: Open
A11: R7 | B11: Format errors in the submissions | C11: Technical & format | D11: 2 | E11: 2 | F11: =D11*E11 -> 4 | G11: =IF(F11>=6,"High",IF(F11>=3,"Medium","Low")) -> Medium | H11: The Formal Requirements and the BMC template impose many formal rules. | I11: Build a checklist from the Formal Requirements and the BMC template (repo name, mandatory folders, .md report, word limits…) and review it before each delivery. Agree an approximate word budget per section from the start. Check the word count on 21/10. | J11: 3.4.5 | K11: Luz | L11: Open
A12: R8 | B12: Technical problems with Git files or GitHub | C12: Technical & format | D12: 2 | E12: 2 | F12: =D12*E12 -> 4 | G12: =IF(F12>=6,"High",IF(F12>=3,"Medium","Low")) -> Medium | H12: Several attempts to fix the folder structure. | I12: Small and frequent commits. Upload deliverables at least 2 h before the deadline. | J12: 1.1.2 | K12: Leyre | L12: Open
A13: R9 | B13: Gantt and Status not kept up to date | C13: Team & planning | D13: 2 | E13: 2 | F13: =D13*E13 -> 4 | G13: =IF(F13>=6,"High",IF(F13>=3,"Medium","Low")) -> Medium | H13: Our first versions of the Gantt and of the Project Status had empty fields and outdated dates. | I13: One owner updates the Project Status and the live Gantt every Monday and Thursday with real dates, status and notes; each member reports their progress at each meeting. | J13: 1.4.1 | K13: Ferran | L13: Open
A14: R10 | B14: Distant species make the comparison hard to interpret | C14: Scientific | D14: 1 | E14: 2 | F14: =D14*E14 -> 2 | G14: =IF(F14>=6,"High",IF(F14>=3,"Medium","Low")) -> Low | H14: The project requires comparing human SOD1 with at least two other species, and the candidates range from close mammals to very distant organisms with much less similar sequences. | I14: Choose species with a clear biological or experimental justification. If the distant species alignment is not informative, replace it with an intermediate one and explain the choice in Methods. | J14: 2.2.1 | K14: Noa | L14: Open
A15: R11 | B15: Online tools unavailable or slow close to the deadline | C15: Technical & format | D15: 1 | E15: 2 | F15: =D15*E15 -> 2 | G15: =IF(F15>=6,"High",IF(F15>=3,"Medium","Low")) -> Low | H15: The tools we need (BLAST, multiple sequence alignment servers) are shared public services with job queues, used by all groups in the same weeks. | I15: Run all analyses early, well before the content freeze; save every output (files + screenshots, with date and tool version). | J15: 2.2.2 | K15: Noa | L15: Open
